Workbook

Sheet 相關性比對
A1: ULLD WAT：測量值 vs 不良率 與 Yield 之相關性比對
A2: 說明：「測量值」為原報告各 Lot 參數測量值；「不良率」為 wat_overview.csv 各測項不良數 ÷ Sites ×100。Spearman 欄位（藍字）由 Python 對 Data 工作表計算後填入（Excel 無內建 Spearman 函數）；Pearson 欄位為 CORREL 公式，會隨 Data 更新。
A4: 測項 | B4: 測量值 vs WAT Yield (Spearman) | C4: 測量值 vs CP Yield (Spearman) | D4: 測量值 vs Yield gap (Spearman) | E4: 不良率 vs WAT Yield (Spearman) | F4: 不良率 vs CP Yield (Spearman) | G4: 不良率 vs Yield gap (Spearman) | H4: 不良率 vs 測量值 (Spearman) | I4: 測量值 vs WAT Yield (Pearson 公式) | J4: 不良率 vs WAT Yield (Pearson 公式) | K4: 方向是否一致 (測量值與不良率 vs WAT)
A5: VSD | B5: 0.312 | C5: 0.275 | D5: 0.083 | E5: -0.002 | F5: -0.017 | G5: 0.005 | H5: 0.008 | I5: =CORREL(Data!$K$2:$K$3056,Data!$F$2:$F$3056) -> 0.39614238 | J5: =CORREL(Data!$AQ$2:$AQ$3056,Data!$F$2:$F$3056) -> -0.0046948678 | K5: =IF(ABS(B5)<0.1,IF(ABS(E5)<0.1,"皆無相關","測量值無相關"),IF(ABS(E5)<0.1,"不良率無相關(不一致)",IF(B5*E5>0,"一致","相反"))) -> 不良率無相關(不一致)
A6: VSD(1mA) | B6: 0.037 | C6: 0.047 | D6: -0.024 | E6: -0.417 | F6: -0.331 | G6: -0.166 | H6: -0.082 | I6: =CORREL(Data!$L$2:$L$3056,Data!$F$2:$F$3056) -> 0.026424463 | J6: =CORREL(Data!$AR$2:$AR$3056,Data!$F$2:$F$3056) -> -0.46903711 | K6: =IF(ABS(B6)<0.1,IF(ABS(E6)<0.1,"皆無相關","測量值無相關"),IF(ABS(E6)<0.1,"不良率無相關(不一致)",IF(B6*E6>0,"一致","相反"))) -> 測量值無相關
A7: IGSSF | B7: -0.04 | C7: 0.004 | D7: -0.039 | E7: -0.739 | F7: -0.575 | G7: -0.248 | H7: 0.012 | I7: =CORREL(Data!$M$2:$M$3056,Data!$F$2:$F$3056) -> -0.021065335 | J7: =CORREL(Data!$AS$2:$AS$3056,Data!$F$2:$F$3056) -> -0.86993524 | K7: =IF(ABS(B7)<0.1,IF(ABS(E7)<0.1,"皆無相關","測量值無相關"),IF(ABS(E7)<0.1,"不良率無相關(不一致)",IF(B7*E7>0,"一致","相反"))) -> 測量值無相關
A8: IGSSR | B8: 0.077 | C8: 0.1 | D8: -0.027 | E8: -0.74 | F8: -0.574 | G8: -0.249 | H8: -0.043 | I8: =CORREL(Data!$N$2:$N$3056,Data!$F$2:$F$3056) -> 0.041856921 | J8: =CORREL(Data!$AT$2:$AT$3056,Data!$F$2:$F$3056) -> -0.869999 | K8: =IF(ABS(B8)<0.1,IF(ABS(E8)<0.1,"皆無相關","測量值無相關"),IF(ABS(E8)<0.1,"不良率無相關(不一致)",IF(B8*E8>0,"一致","相反"))) -> 測量值無相關
A9: IGSSF_26 | B9: -0.033 | C9: 0.019 | D9: -0.05 | E9: -0.74 | F9: -0.573 | G9: -0.253 | H9: 0.012 | I9: =CORREL(Data!$O$2:$O$3056,Data!$F$2:$F$3056) -> -0.015778565 | J9: =CORREL(Data!$AU$2:$AU$3056,Data!$F$2:$F$3056) -> -0.87303551 | K9: =IF(ABS(B9)<0.1,IF(ABS(E9)<0.1,"皆無相關","測量值無相關"),IF(ABS(E9)<0.1,"不良率無相關(不一致)",IF(B9*E9>0,"一致","相反"))) -> 測量值無相關
A10: IGSSR_26 | B10: 0.064 | C10: 0.082 | D10: -0.016 | E10: -0.743 | F10: -0.574 | G10: -0.256 | H10: -0.046 | I10: =CORREL(Data!$P$2:$P$3056,Data!$F$2:$F$3056) -> 0.02283358 | J10: =CORREL(Data!$AV$2:$AV$3056,Data!$F$2:$F$3056) -> -0.87437673 | K10: =IF(ABS(B10)<0.1,IF(ABS(E10)<0.1,"皆無相關","測量值無相關"),IF(ABS(E10)<0.1,"不良率無相關(不一致)",IF(B10*E10>0,"一致","相反"))) -> 測量值無相關
A11: VT(50uA) | B11: 0.058 | C11: 0.033 | D11: 0.029 | E11: -0.864 | F11: -0.681 | G11: -0.301 | H11: -0.042 | I11: =CORREL(Data!$Q$2:$Q$3056,Data!$F$2:$F$3056) -> 0.046574603 | J11: =CORREL(Data!$AW$2:$AW$3056,Data!$F$2:$F$3056) -> -0.91898396 | K11: =IF(ABS(B11)<0.1,IF(ABS(E11)<0.1,"皆無相關","測量值無相關"),IF(ABS(E11)<0.1,"不良率無相關(不一致)",IF(B11*E11>0,"一致","相反"))) -> 測量值無相關
A12: VT(250uA) | B12: 0.067 | C12: 0.04 | D12: 0.03 | E12: -0.751 | F12: -0.611 | G12: -0.252 | H12: -0.027 | I12: =CORREL(Data!$R$2:$R$3056,Data!$F$2:$F$3056) -> 0.056333814 | J12: =CORREL(Data!$AX$2:$AX$3056,Data!$F$2:$F$3056) -> -0.80482273 | K12: =IF(ABS(B12)<0.1,IF(ABS(E12)<0.1,"皆無相關","測量值無相關"),IF(ABS(E12)<0.1,"不良率無相關(不一致)",IF(B12*E12>0,"一致","相反"))) -> 測量值無相關
A13: IDSS | B13: -0.027 | C13: 0.027 | D13: -0.04 | E13: -0.832 | F13: -0.637 | G13: -0.34 | H13: 0.048 | I13: =CORREL(Data!$S$2:$S$3056,Data!$F$2:$F$3056) -> -0.032907524 | J13: =CORREL(Data!$AY$2:$AY$3056,Data!$F$2:$F$3056) -> -0.87829998 | K13: =IF(ABS(B13)<0.1,IF(ABS(E13)<0.1,"皆無相關","測量值無相關"),IF(ABS(E13)<0.1,"不良率無相關(不一致)",IF(B13*E13>0,"一致","相反"))) -> 測量值無相關
A14: BVDS_100uA | B14: 0.034 | C14: -0.009 | D14: 0.026 | E14: -0.76 | F14: -0.583 | G14: -0.301 | H14: -0.213 | I14: =CORREL(Data!$T$2:$T$3056,Data!$F$2:$F$3056) -> 0.033790078 | J14: =CORREL(Data!$AZ$2:$AZ$3056,Data!$F$2:$F$3056) -> -0.83639683 | K14: =IF(ABS(B14)<0.1,IF(ABS(E14)<0.1,"皆無相關","測量值無相關"),IF(ABS(E14)<0.1,"不良率無相關(不一致)",IF(B14*E14>0,"一致","相反"))) -> 測量值無相關
A15: BVDS | B15: 0.017 | C15: -0.021 | D15: 0.02 | E15: -0.674 | F15: -0.525 | G15: -0.265 | H15: -0.129 | I15: =CORREL(Data!$U$2:$U$3056,Data!$F$2:$F$3056) -> 0.010010135 | J15: =CORREL(Data!$BA$2:$BA$3056,Data!$F$2:$F$3056) -> -0.7427433 | K15: =IF(ABS(B15)<0.1,IF(ABS(E15)<0.1,"皆無相關","測量值無相關"),IF(ABS(E15)<0.1,"不良率無相關(不一致)",IF(B15*E15>0,"一致","相反"))) -> 測量值無相關
A16: BVDS_10mA | B16: 0.014 | C16: -0.023 | D16: 0.018 | E16: -0.422 | F16: -0.325 | G16: -0.183 | H16: -0.003 | I16: =CORREL(Data!$V$2:$V$3056,Data!$F$2:$F$3056) -> 0.0015788328 | J16: =CORREL(Data!$BB$2:$BB$3056,Data!$F$2:$F$3056) -> -0.40282897 | K16: =IF(ABS(B16)<0.1,IF(ABS(E16)<0.1,"皆無相關","測量值無相關"),IF(ABS(E16)<0.1,"不良率無相關(不一致)",IF(B16*E16>0,"一致","相反"))) -> 測量值無相關
A17: IGSSF_1 | B17: -0.071 | C17: -0.091 | D17: 0.04 | E17: -0.741 | F17: -0.575 | G17: -0.252 | H17: 0.026 | I17: =CORREL(Data!$W$2:$W$3056,Data!$F$2:$F$3056) -> -0.0089675403 | J17: =CORREL(Data!$BC$2:$BC$3056,Data!$F$2:$F$3056) -> -0.87356405 | K17: =IF(ABS(B17)<0.1,IF(ABS(E17)<0.1,"皆無相關","測量值無相關"),IF(ABS(E17)<0.1,"不良率無相關(不一致)",IF(B17*E17>0,"一致","相反"))) -> 測量值無相關
A18: IGSSR_1 | B18: 0.061 | C18: 0.094 | D18: -0.007 | E18: -0.741 | F18: -0.574 | G18: -0.251 | H18: -0.023 | I18: =CORREL(Data!$X$2:$X$3056,Data!$F$2:$F$3056) -> 0.033899075 | J18: =CORREL(Data!$BD$2:$BD$3056,Data!$F$2:$F$3056) -> -0.87381857 | K18: =IF(ABS(B18)<0.1,IF(ABS(E18)<0.1,"皆無相關","測量值無相關"),IF(ABS(E18)<0.1,"不良率無相關(不一致)",IF(B18*E18>0,"一致","相反"))) -> 測量值無相關
A19: DBV | B19: -0.412 | C19: -0.334 | D19: -0.132 | E19: -0.766 | F19: -0.586 | G19: -0.306 | H19: 0.197 | I19: =CORREL(Data!$Y$2:$Y$3056,Data!$F$2:$F$3056) -> -0.52950628 | J19: =CORREL(Data!$BE$2:$BE$3056,Data!$F$2:$F$3056) -> -0.8374429 | K19: =IF(ABS(B19)<0.1,IF(ABS(E19)<0.1,"皆無相關","測量值無相關"),IF(ABS(E19)<0.1,"不良率無相關(不一致)",IF(B19*E19>0,"一致","相反"))) -> 一致
A20: DBV_1mA | B20: -0.044 | C20: -0.095 | D20: 0.059 | E20: -0.737 | F20: -0.557 | G20: -0.322 | H20: 0.055 | I20: =CORREL(Data!$Z$2:$Z$3056,Data!$F$2:$F$3056) -> -0.048702329 | J20: =CORREL(Data!$BF$2:$BF$3056,Data!$F$2:$F$3056) -> -0.81741561 | K20: =IF(ABS(B20)<0.1,IF(ABS(E20)<0.1,"皆無相關","測量值無相關"),IF(ABS(E20)<0.1,"不良率無相關(不一致)",IF(B20*E20>0,"一致","相反"))) -> 測量值無相關
A21: 平均 |ρ| | B21: =SUMPRODUCT(ABS(B5:B20))/COUNT(B5:B20) -> 0.0855 | C21: =SUMPRODUCT(ABS(C5:C20))/COUNT(C5:C20) -> 0.080875 | D21: =SUMPRODUCT(ABS(D5:D20))/COUNT(D5:D20) -> 0.04 | E21: =SUMPRODUCT(ABS(E5:E20))/COUNT(E5:E20) -> 0.6668125 | F21: =SUMPRODUCT(ABS(F5:F20))/COUNT(F5:F20) -> 0.518625 | G21: =SUMPRODUCT(ABS(G5:G20))/COUNT(G5:G20) -> 0.246875 | H21: =SUMPRODUCT(ABS(H5:H20))/COUNT(H5:H20) -> 0.060375
A23: 重點結論
A24: 1. 兩者量的是不同東西：不良率與 Yield 幾乎全為強負相關（預期，不良數決定 Yield）；測量值僅 DBV(-0.41)、VSD(+0.31) 有明顯相關，其餘接近 0。
A25: 2. DBV 兩者方向一致（測量值 -0.41、不良率 -0.77），且 DBV 測量值與其不良率呈正相關（+0.20）。
A26: 3. VSD 不一致：測量值 vs Yield 為 +0.31，但 VSD 不良率 vs Yield 約 0，代表 VSD 並非靠不良顆數影響 Yield，+0.31 較像 Lot／批次差異，不宜解讀為 VSD 不良造成損失。
A27: 4. 其他測項的測量值與自身不良率幾乎無關（|ρ| 多 <0.05），故測量值平均相關看不出其損失貢獻。
A28: 5. 各 IGSS 測項不良率彼此高度相關（約 -0.74），顯示其不良顆數大多為同一批顆粒。
A29: 6. 相關不等於因果；比對基於兩份資料皆有的 3,055 個 Lot。

Sheet Lot Type
A1: Lot Type（PRODUCT ID 後三碼）與 Yield
A3: Lot Type | B3: Lot 數 | C3: 平均 WAT Yield(%) | D3: 平均 CP Yield(%) | E3: 平均 Yield gap
A4: 02U | B4: =COUNTIF(Data!$C$2:$C$3056,A4) -> 194 | C4: =AVERAGEIFS(Data!$F$2:$F$3056,Data!$C$2:$C$3056,A4) -> 93.403093 | D4: =AVERAGEIFS(Data!$I$2:$I$3056,Data!$C$2:$C$3056,A4) -> 92.044551 | E4: =AVERAGEIFS(Data!$J$2:$J$3056,Data!$C$2:$C$3056,A4) -> 1.4161236
A5: 03U | B5: =COUNTIF(Data!$C$2:$C$3056,A5) -> 1898 | C5: =AVERAGEIFS(Data!$F$2:$F$3056,Data!$C$2:$C$3056,A5) -> 93.533772 | D5: =AVERAGEIFS(Data!$I$2:$I$3056,Data!$C$2:$C$3056,A5) -> 92.226971 | E5: =AVERAGEIFS(Data!$J$2:$J$3056,Data!$C$2:$C$3056,A5) -> 1.4171761
A6: 04U | B6: =COUNTIF(Data!$C$2:$C$3056,A6) -> 348 | C6: =AVERAGEIFS(Data!$F$2:$F$3056,Data!$C$2:$C$3056,A6) -> 93.481609 | D6: =AVERAGEIFS(Data!$I$2:$I$3056,Data!$C$2:$C$3056,A6) -> 92.139069 | E6: =AVERAGEIFS(Data!$J$2:$J$3056,Data!$C$2:$C$3056,A6) -> 1.337027
A7: 06U | B7: =COUNTIF(Data!$C$2:$C$3056,A7) -> 73 | C7: =AVERAGEIFS(Data!$F$2:$F$3056,Data!$C$2:$C$3056,A7) -> 93.654795 | D7: =AVERAGEIFS(Data!$I$2:$I$3056,Data!$C$2:$C$3056,A7) -> 92.819825 | E7: =AVERAGEIFS(Data!$J$2:$J$3056,Data!$C$2:$C$3056,A7) -> 1.054386
A8: 07U | B8: =COUNTIF(Data!$C$2:$C$3056,A8) -> 484 | C8: =AVERAGEIFS(Data!$F$2:$F$3056,Data!$C$2:$C$3056,A8) -> 93.483058 | D8: =AVERAGEIFS(Data!$I$2:$I$3056,Data!$C$2:$C$3056,A8) -> 92.710997 | E8: =AVERAGEIFS(Data!$J$2:$J$3056,Data!$C$2:$C$3056,A8) -> 1.2261942
A9: 08U | B9: =COUNTIF(Data!$C$2:$C$3056,A9) -> 55 | C9: =AVERAGEIFS(Data!$F$2:$F$3056,Data!$C$2:$C$3056,A9) -> 94.476364 | D9: =AVERAGEIFS(Data!$I$2:$I$3056,Data!$C$2:$C$3056,A9) -> 93.577273 | E9: =AVERAGEIFS(Data!$J$2:$J$3056,Data!$C$2:$C$3056,A9) -> 0.99545455
A12: η²（Lot Type 對 WAT Yield） | D12: 0.0015
A13: η²（Lot Type 對 CP Yield） | D13: 0.0141
A14: 註：η² 由 Python 計算（相關比，Lot Type 解釋之變異比例），藍字為硬編碼；兩者皆很小，Lot Type 對 Yield 影響有限。與原報告 Part No 結論一致。

Sheet 資料品質
A1: 資料品質檢查
A3: 項目 | B3: 數值 | C3: 備註
A4: CSV Lot 數（wat_overview.csv） | B4: 3152 | C4: 來源：附件 wat_overview.csv
A5: 原報告 Lot 數 | B5: 3058 | C5: 來源：ULLD_WAT_CP_Summary
A6: 兩份資料皆有的 Lot 數（本表分析對象） | B6: =COUNTA(Data!A2:A3056) -> 3055 | C6: Data 工作表列數
A7: Yield 差 > 0.5 個百分點的 Lot 數 | B7: =COUNTIF(Data!H2:H3056,">0.5") -> 115 | C7: CSV Yield 與原報告 WAT Yield
A8: Yield 差 > 1 個百分點的 Lot 數 | B8: =COUNTIF(Data!H2:H3056,">1") -> 21
A9: Yield 差最大值（百分點） | B9: =MAX(Data!H2:H3056) -> 13 | C9: 多半因片數不同（如片數 12）
A10: Lot Type 與 Part No 可比對 Lot 數 | B10: =COUNTA(Data!D2:D3056) -> 3051 | C10: Part No 缺值者不計
A11: 其中 Lot Type 與 Part No 不一致數 | B11: =SUMPRODUCT((Data!D2:D3056<>"")*(Data!C2:C3056<>Data!D2:D3056)) -> 0 | C11: 0 表示完全一致
A12: CSV 中 Lot Type 為 001/002 的 Lot 數 | B12: 8 | C12: 來源：wat_overview.csv（001:5、002:3）；非一般 Lot Type，這些 Lot 不在 3,055 個比對 Lot 內，未納入 Lot Type 分析

Sheet Data
A1: Lot | B1: PRODUCT ID | C1: Lot Type(PRODUCT ID後三碼) | D1: Part No(原報告) | E1: Sites | F1: WAT Yield(CSV,%) | G1: WAT Yield(原報告,%) | H1: Yield差(絕對值) | I1: CP Yield(%) | J1: Yield gap | K1: VSD 測量值 | L1: VSD(1mA) 測量值 | M1: IGSSF 測量值 | N1: IGSSR 測量值 | O1: IGSSF_26 測量值 | P1: IGSSR_26 測量值 | Q1: VT(50uA) 測量值 | R1: VT(250uA) 測量值 | S1: IDSS 測量值 | T1: BVDS_100uA 測量值 | U1: BVDS 測量值 | V1: BVDS_10mA 測量值 | W1: IGSSF_1 測量值 | X1: IGSSR_1 測量值 | Y1: DBV 測量值 | Z1: DBV_1mA 測量值 | AA1: VSD 不良數 | AB1: VSD(1mA) 不良數 | AC1: IGSSF 不良數 | AD1: IGSSR 不良數 | AE1: IGSSF_26 不良數 | AF1: IGSSR_26 不良數 | AG1: VT(50uA) 不良數 | AH1: VT(250uA) 不良數 | AI1: IDSS 不良數 | AJ1: BVDS_100uA 不良數 | AK1: BVDS 不良數 | AL1: BVDS_10mA 不良數 | AM1: IGSSF_1 不良數 | AN1: IGSSR_1 不良數 | AO1: DBV 不良數 | AP1: DBV_1mA 不良數 | AQ1: VSD 不良率(%) | AR1: VSD(1mA) 不良率(%) | AS1: IGSSF 不良率(%) | AT1: IGSSR 不良率(%) | AU1: IGSSF_26 不良率(%) | AV1: IGSSR_26 不良率(%) | AW1: VT(50uA) 不良率(%) | AX1: VT(250uA) 不良率(%) | AY1: IDSS 不良率(%) | AZ1: BVDS_100uA 不良率(%) | BA1: BVDS 不良率(%) | BB1: BVDS_10mA 不良率(%) | BC1: IGSSF_1 不良率(%) | BD1: IGSSR_1 不良率(%) | BE1: DBV 不良率(%) | BF1: DBV_1mA 不良率(%)
A2: RP67156 | B2: P40AR002N20007U | C2: 07U | D2: 07U | E2: 500 | F2: 93.4 | G2: 93.4 | H2: =ABS(F2-G2) -> 0 | I2: 90.43 | J2: 2.97 | K2: 0.430816 | L2: 0.47526923 | M2: 0.27789496 | N2: -0.40968277 | O2: 0.51486611 | P2: -0.72099163 | Q2: 2.2168632 | R2: 2.3783784 | S2: 4.7974685 | T2: 21.203132 | U2: 21.234029 | V2: 21.265644 | W2: 0.37217992 | X2: -0.37409205 | Y2: 0.059046025 | Z2: 0.029367769 | AA2: 0 | AB2: 6 | AC2: 24 | AD2: 24 | AE2: 22 | AF2: 22 | AG2: 25 | AH2: 17 | AI2: 24 | AJ2: 21 | AK2: 16 | AL2: 5 | AM2: 22 | AN2: 22 | AO2: 22 | AP2: 16 | AQ2: =IF(AA2="","",AA2/$E2*100) -> 0 | AR2: =IF(AB2="","",AB2/$E2*100) -> 1.2 | AS2: =IF(AC2="","",AC2/$E2*100) -> 4.8 | AT2: =IF(AD2="","",AD2/$E2*100) -> 4.8 | AU2: =IF(AE2="","",AE2/$E2*100) -> 4.4 | AV2: =IF(AF2="","",AF2/$E2*100) -> 4.4 | AW2: =IF(AG2="","",AG2/$E2*100) -> 5 | AX2: =IF(AH2="","",AH2/$E2*100) -> 3.4 | ... BF2: =IF(AP2="","",AP2/$E2*100) -> 3.2
A3: RP67440 | B3: P40AR002N20003U | C3: 03U | D3: 03U | E3: 480 | F3: 86.9 | G3: 87.08 | H3: =ABS(F3-G3) -> 0.18 | I3: 87.21 | J3: -0.13 | K3: 0.43475792 | L3: 0.47860549 | M3: 0.28777342 | N3: -0.40904575 | O3: 0.52061656 | P3: -0.66479739 | Q3: 2.3839238 | R3: 2.5487473 | S3: 4.1653917 | T3: 21.538479 | U3: 21.591429 | V3: 21.625636 | W3: 0.35841176 | X3: -0.3691634 | Y3: 0.073307692 | Z3: 0.031268293 | AA3: 0 | AB3: 6 | AC3: 21 | AD3: 21 | AE3: 21 | AF3: 21 | AG3: 34 | AH3: 23 | AI3: 46 | AJ3: 33 | AK3: 22 | AL3: 3 | AM3: 21 | AN3: 21 | AO3: 38 | AP3: 29 | AQ3: =IF(AA3="","",AA3/$E3*100) -> 0 | AR3: =IF(AB3="","",AB3/$E3*100) -> 1.25 | AS3: =IF(AC3="","",AC3/$E3*100) -> 4.375 | AT3: =IF(AD3="","",AD3/$E3*100) -> 4.375 | AU3: =IF(AE3="","",AE3/$E3*100) -> 4.375 | AV3: =IF(AF3="","",AF3/$E3*100) -> 4.375 | AW3: =IF(AG3="","",AG3/$E3*100) -> 7.0833333 | AX3: =IF(AH3="","",AH3/$E3*100) -> 4.7916667 | ... BF3: =IF(AP3="","",AP3/$E3*100) -> 6.0416667
A4: RP67443 | B4: P40AR002N20003U | C4: 03U | D4: 03U | E4: 500 | F4: 92.8 | G4: 93 | H4: =ABS(F4-G4) -> 0.2 | I4: 89.95 | J4: 3.05 | K4: 0.4340484 | L4: 0.47620363 | M4: 0.29133333 | N4: -0.42384072 | O4: 0.55137342 | P4: -0.74664346 | Q4: 2.3352331 | R4: 2.4975876 | S4: 4.7154772 | T4: 21.53313 | U4: 21.582485 | V4: 21.610998 | W4: 0.36882489 | X4: -0.38422321 | Y4: 0.07685947 | Z4: 0.02545935 | AA4: 0 | AB4: 4 | AC4: 26 | AD4: 26 | AE4: 26 | AF4: 26 | AG4: 28 | AH4: 13 | AI4: 18 | AJ4: 8 | AK4: 5 | AL4: 2 | AM4: 26 | AN4: 26 | AO4: 9 | AP4: 8 | AQ4: =IF(AA4="","",AA4/$E4*100) -> 0 | AR4: =IF(AB4="","",AB4/$E4*100) -> 0.8 | AS4: =IF(AC4="","",AC4/$E4*100) -> 5.2 | AT4: =IF(AD4="","",AD4/$E4*100) -> 5.2 | AU4: =IF(AE4="","",AE4/$E4*100) -> 5.2 | AV4: =IF(AF4="","",AF4/$E4*100) -> 5.2 | AW4: =IF(AG4="","",AG4/$E4*100) -> 5.6 | AX4: =IF(AH4="","",AH4/$E4*100) -> 2.6 | ... BF4: =IF(AP4="","",AP4/$E4*100) -> 1.6
A5: RP67458 | B5: P40AR002N20003U | C5: 03U | D5: 03U | E5: 500 | F5: 95.4 | G5: 95.4 | H5: =ABS(F5-G5) -> 0 | I5: 93.83 | J5: 1.57 | K5: 0.4470448 | L5: 0.48768474 | M5: 0.33424431 | N5: -0.41186542 | O5: 0.58659959 | P5: -0.87614315 | Q5: 2.1617635 | R5: 2.317 | S5: 4.3773061 | T5: 21.315213 | U5: 21.338586 | V5: 21.38755 | W5: 0.32485062 | X5: -0.40856017 | Y5: 0.071022312 | Z5: 0.046020284 | AA5: 0 | AB5: 2 | AC5: 17 | AD5: 17 | AE5: 18 | AF5: 18 | AG5: 18 | AH5: 9 | AI5: 10 | AJ5: 7 | AK5: 5 | AL5: 2 | AM5: 18 | AN5: 18 | AO5: 7 | AP5: 7 | AQ5: =IF(AA5="","",AA5/$E5*100) -> 0 | AR5: =IF(AB5="","",AB5/$E5*100) -> 0.4 | AS5: =IF(AC5="","",AC5/$E5*100) -> 3.4 | AT5: =IF(AD5="","",AD5/$E5*100) -> 3.4 | AU5: =IF(AE5="","",AE5/$E5*100) -> 3.6 | AV5: =IF(AF5="","",AF5/$E5*100) -> 3.6 | AW5: =IF(AG5="","",AG5/$E5*100) -> 3.6 | AX5: =IF(AH5="","",AH5/$E5*100) -> 1.8 | ... BF5: =IF(AP5="","",AP5/$E5*100) -> 1.4
A6: RP67460 | B6: P40AR002N20003U | C6: 03U | D6: 03U | E6: 500 | F6: 95.8 | G6: 95.8 | H6: =ABS(F6-G6) -> 0 | I6: 94.6 | J6: 1.2 | K6: 0.4470984 | L6: 0.48929293 | M6: 0.27417647 | N6: -0.3920426 | O6: 0.54793915 | P6: -0.68464228 | Q6: 2.280883 | R6: 2.4405263 | S6: 4.4822016 | T6: 21.166191 | U6: 21.197967 | V6: 21.243347 | W6: 0.29985801 | X6: -0.3788499 | Y6: 0.083391481 | Z6: 0.04651626 | AA6: 0 | AB6: 5 | AC6: 7 | AD6: 7 | AE6: 7 | AF6: 7 | AG6: 13 | AH6: 6 | AI6: 14 | AJ6: 9 | AK6: 6 | AL6: 4 | AM6: 7 | AN6: 7 | AO6: 7 | AP6: 8 | AQ6: =IF(AA6="","",AA6/$E6*100) -> 0 | AR6: =IF(AB6="","",AB6/$E6*100) -> 1 | AS6: =IF(AC6="","",AC6/$E6*100) -> 1.4 | AT6: =IF(AD6="","",AD6/$E6*100) -> 1.4 | AU6: =IF(AE6="","",AE6/$E6*100) -> 1.4 | AV6: =IF(AF6="","",AF6/$E6*100) -> 1.4 | AW6: =IF(AG6="","",AG6/$E6*100) -> 2.6 | AX6: =IF(AH6="","",AH6/$E6*100) -> 1.2 | ... BF6: =IF(AP6="","",AP6/$E6*100) -> 1.6
A7: RP67467 | B7: P40AR002N20003U | C7: 03U | D7: 03U | E7: 500 | F7: 96.6 | G7: 96.8 | H7: =ABS(F7-G7) -> 0.2 | I7: 94.79 | J7: 2.01 | K7: 0.4344068 | L7: 0.47498994 | M7: 0.30261336 | N7: -0.47689091 | O7: 0.55526721 | P7: -0.73166194 | Q7: 2.1692213 | R7: 2.3307317 | S7: 4.5163136 | T7: 20.986179 | U7: 21.012779 | V7: 21.039718 | W7: 0.37660729 | X7: -0.39190688 | Y7: 0.052389452 | Z7: 0.024435845 | AA7: 0 | AB7: 3 | AC7: 6 | AD7: 5 | AE7: 6 | AF7: 6 | AG7: 12 | AH7: 8 | AI7: 9 | AJ7: 8 | AK7: 6 | AL7: 4 | AM7: 6 | AN7: 6 | AO7: 7 | AP7: 9 | AQ7: =IF(AA7="","",AA7/$E7*100) -> 0 | AR7: =IF(AB7="","",AB7/$E7*100) -> 0.6 | AS7: =IF(AC7="","",AC7/$E7*100) -> 1.2 | AT7: =IF(AD7="","",AD7/$E7*100) -> 1 | AU7: =IF(AE7="","",AE7/$E7*100) -> 1.2 | AV7: =IF(AF7="","",AF7/$E7*100) -> 1.2 | AW7: =IF(AG7="","",AG7/$E7*100) -> 2.4 | AX7: =IF(AH7="","",AH7/$E7*100) -> 1.6 | ... BF7: =IF(AP7="","",AP7/$E7*100) -> 1.8
A8: RP67474 | B8: P40AR002N20003U | C8: 03U | D8: 03U | E8: 500 | F8: 96 | G8: 96 | H8: =ABS(F8-G8) -> 0 | I8: 94.89 | J8: 1.11 | K8: 0.4328676 | L8: 0.47585425 | M8: 0.27574286 | N8: -0.40008367 | O8: 0.51423673 | P8: -0.68665102 | Q8: 2.2037037 | R8: 2.3675306 | S8: 3.9233126 | T8: 21.021355 | U8: 21.055285 | V8: 21.08404 | W8: 0.33728163 | X8: -0.36426082 | Y8: 0.064211382 | Z8: 0.023991837 | AA8: 0 | AB8: 6 | AC8: 10 | AD8: 10 | AE8: 10 | AF8: 10 | AG8: 14 | AH8: 10 | AI8: 17 | AJ8: 13 | AK8: 8 | AL8: 5 | AM8: 10 | AN8: 10 | AO8: 8 | AP8: 10 | AQ8: =IF(AA8="","",AA8/$E8*100) -> 0 | AR8: =IF(AB8="","",AB8/$E8*100) -> 1.2 | AS8: =IF(AC8="","",AC8/$E8*100) -> 2 | AT8: =IF(AD8="","",AD8/$E8*100) -> 2 | AU8: =IF(AE8="","",AE8/$E8*100) -> 2 | AV8: =IF(AF8="","",AF8/$E8*100) -> 2 | AW8: =IF(AG8="","",AG8/$E8*100) -> 2.8 | AX8: =IF(AH8="","",AH8/$E8*100) -> 2 | ... BF8: =IF(AP8="","",AP8/$E8*100) -> 2
A9: RP67508 | B9: P40AR002N20003U | C9: 03U | D9: 03U | E9: 500 | F9: 91.8 | G9: 91.8 | H9: =ABS(F9-G9) -> 0 | I9: 90.68 | J9: 1.12 | K9: 0.4469608 | L9: 0.49028571 | M9: 0.26192373 | N9: -0.37223305 | O9: 0.50110593 | P9: -0.65148837 | Q9: 2.2942038 | R9: 2.4533125 | S9: 4.3491597 | T9: 21.416701 | U9: 21.443424 | V9: 21.492197 | W9: 0.29310759 | X9: -0.36793882 | Y9: 0.088835073 | Z9: 0.054521921 | AA9: 0 | AB9: 3 | AC9: 28 | AD9: 28 | AE9: 28 | AF9: 26 | AG9: 29 | AH9: 20 | AI9: 24 | AJ9: 21 | AK9: 16 | AL9: 3 | AM9: 26 | AN9: 26 | AO9: 21 | AP9: 21 | AQ9: =IF(AA9="","",AA9/$E9*100) -> 0 | AR9: =IF(AB9="","",AB9/$E9*100) -> 0.6 | AS9: =IF(AC9="","",AC9/$E9*100) -> 5.6 | AT9: =IF(AD9="","",AD9/$E9*100) -> 5.6 | AU9: =IF(AE9="","",AE9/$E9*100) -> 5.6 | AV9: =IF(AF9="","",AF9/$E9*100) -> 5.2 | AW9: =IF(AG9="","",AG9/$E9*100) -> 5.8 | AX9: =IF(AH9="","",AH9/$E9*100) -> 4 | ... BF9: =IF(AP9="","",AP9/$E9*100) -> 4.2
A10: RP67509 | B10: P40AR002N20003U | C10: 03U | D10: 03U | E10: 500 | F10: 93.2 | G10: 93.2 | H10: =ABS(F10-G10) -> 0 | I10: 91.88 | J10: 1.32 | K10: 0.4432036 | L10: 0.48919067 | M10: 0.27410105 | N10: -0.39446105 | O10: 0.53807789 | P10: -0.69731646 | Q10: 2.2818763 | R10: 2.4415866 | S10: 4.598309 | T10: 21.152893 | U10: 21.189117 | V10: 21.230505 | W10: 0.30865401 | X10: -0.39238819 | Y10: 0.073271222 | Z10: 0.042152893 | AA10: 0 | AB10: 7 | AC10: 25 | AD10: 25 | AE10: 25 | AF10: 26 | AG10: 31 | AH10: 20 | AI10: 21 | AJ10: 16 | AK10: 13 | AL10: 5 | AM10: 26 | AN10: 26 | AO10: 17 | AP10: 16 | AQ10: =IF(AA10="","",AA10/$E10*100) -> 0 | AR10: =IF(AB10="","",AB10/$E10*100) -> 1.4 | AS10: =IF(AC10="","",AC10/$E10*100) -> 5 | AT10: =IF(AD10="","",AD10/$E10*100) -> 5 | AU10: =IF(AE10="","",AE10/$E10*100) -> 5 | AV10: =IF(AF10="","",AF10/$E10*100) -> 5.2 | AW10: =IF(AG10="","",AG10/$E10*100) -> 6.2 | AX10: =IF(AH10="","",AH10/$E10*100) -> 4 | ... BF10: =IF(AP10="","",AP10/$E10*100) -> 3.2
A11: RP67517 | B11: P40AR002N20003U | C11: 03U | D11: 03U | E11: 500 | F11: 96.2 | G11: 96.2 | H11: =ABS(F11-G11) -> 0 | I11: 94.34 | J11: 1.86 | K11: 0.4493616 | L11: 0.48922244 | M11: 0.28964787 | N11: -0.41766531 | O11: 0.59339676 | P11: -0.81243725 | Q11: 2.2411704 | R11: 2.3990303 | S11: 4.1775154 | T11: 20.826489 | U11: 20.859229 | V11: 20.90501 | W11: 0.3285 | X11: -0.40698178 | Y11: 0.08047541 | Z11: 0.039192623 | AA11: 0 | AB11: 1 | AC11: 7 | AD11: 7 | AE11: 6 | AF11: 6 | AG11: 13 | AH11: 5 | AI11: 13 | AJ11: 13 | AK11: 7 | AL11: 1 | AM11: 6 | AN11: 6 | AO11: 12 | AP11: 12 | AQ11: =IF(AA11="","",AA11/$E11*100) -> 0 | AR11: =IF(AB11="","",AB11/$E11*100) -> 0.2 | AS11: =IF(AC11="","",AC11/$E11*100) -> 1.4 | AT11: =IF(AD11="","",AD11/$E11*100) -> 1.4 | AU11: =IF(AE11="","",AE11/$E11*100) -> 1.2 | AV11: =IF(AF11="","",AF11/$E11*100) -> 1.2 | AW11: =IF(AG11="","",AG11/$E11*100) -> 2.6 | AX11: =IF(AH11="","",AH11/$E11*100) -> 1 | ... BF11: =IF(AP11="","",AP11/$E11*100) -> 2.4
A12: RP67531 | B12: P40AR002N20003U | C12: 03U | D12: 03U | E12: 500 | F12: 96.6 | G12: 96.6 | H12: =ABS(F12-G12) -> 0 | I12: 93.9 | J12: 2.7 | K12: 0.4474412 | L12: 0.48843775 | M12: 0.28492798 | N12: -0.41473868 | O12: 0.60097727 | P12: -0.7678781 | Q12: 2.2516116 | R12: 2.4084254 | S12: 5.7146217 | T12: 21.513849 | U12: 21.521472 | V12: 21.562272 | W12: 0.3201405 | X12: -0.39519215 | Y12: 0.052714286 | Z12: 0.03685947 | AA12: 0 | AB12: 2 | AC12: 14 | AD12: 14 | AE12: 16 | AF12: 16 | AG12: 16 | AH12: 10 | AI12: 11 | AJ12: 9 | AK12: 6 | AL12: 2 | AM12: 16 | AN12: 16 | AO12: 10 | AP12: 9 | AQ12: =IF(AA12="","",AA12/$E12*100) -> 0 | AR12: =IF(AB12="","",AB12/$E12*100) -> 0.4 | AS12: =IF(AC12="","",AC12/$E12*100) -> 2.8 | AT12: =IF(AD12="","",AD12/$E12*100) -> 2.8 | AU12: =IF(AE12="","",AE12/$E12*100) -> 3.2 | AV12: =IF(AF12="","",AF12/$E12*100) -> 3.2 | AW12: =IF(AG12="","",AG12/$E12*100) -> 3.2 | AX12: =IF(AH12="","",AH12/$E12*100) -> 2 | ... BF12: =IF(AP12="","",AP12/$E12*100) -> 1.8
A13: RP67532 | B13: P40AR002N20003U | C13: 03U | D13: 03U | E13: 500 | F13: 93.4 | G13: 93.4 | H13: =ABS(F13-G13) -> 0 | I13: 94.14 | J13: -0.74 | K13: 0.4475508 | L13: 0.48878514 | M13: 0.29097314 | N13: -0.42894215 | O13: 0.61658178 | P13: -0.76702277 | Q13: 2.2979916 | R13: 2.4573814 | S13: 5.8308386 | T13: 21.09125 | U13: 21.124025 | V13: 21.162222 | W13: 0.3335176 | X13: -0.4055528 | Y13: 0.072586279 | Z13: 0.031983402 | AA13: 0 | AB13: 2 | AC13: 16 | AD13: 16 | AE13: 17 | AF13: 17 | AG13: 22 | AH13: 13 | AI13: 23 | AJ13: 20 | AK13: 13 | AL13: 5 | AM13: 17 | AN13: 17 | AO13: 19 | AP13: 18 | AQ13: =IF(AA13="","",AA13/$E13*100) -> 0 | AR13: =IF(AB13="","",AB13/$E13*100) -> 0.4 | AS13: =IF(AC13="","",AC13/$E13*100) -> 3.2 | AT13: =IF(AD13="","",AD13/$E13*100) -> 3.2 | AU13: =IF(AE13="","",AE13/$E13*100) -> 3.4 | AV13: =IF(AF13="","",AF13/$E13*100) -> 3.4 | AW13: =IF(AG13="","",AG13/$E13*100) -> 4.4 | AX13: =IF(AH13="","",AH13/$E13*100) -> 2.6 | ... BF13: =IF(AP13="","",AP13/$E13*100) -> 3.6
... A699: RP68510 | B699: P40AR002N20003U | C699: 03U | D699: 03U | E699: 500 | F699: 95.6 | G699: 95.8 | H699: =ABS(F699-G699) -> 0.2 | I699: 94.64 | J699: 1.16 | K699: 0.44737 | L699: 0.48828571 | M699: 0.30447336 | N699: -0.46232172 | O699: 0.66486626 | P699: -0.86914609 | Q699: 2.3955694 | R699: 2.5530204 | S699: 5.3589938 | T699: 21.04277 | U699: 21.080202 | V699: 21.106452 | W699: 0.39395679 | X699: -0.43896914 | Y699: 0.062598778 | Z699: 0.02542915 | AA699: 0 | AB699: 3 | AC699: 12 | AD699: 12 | AE699: 14 | AF699: 14 | AG699: 17 | AH699: 9 | AI699: 13 | AJ699: 9 | AK699: 5 | AL699: 4 | AM699: 14 | AN699: 14 | AO699: 9 | AP699: 6 | AQ699: =IF(AA699="","",AA699/$E699*100) -> 0 | AR699: =IF(AB699="","",AB699/$E699*100) -> 0.6 | AS699: =IF(AC699="","",AC699/$E699*100) -> 2.4 | AT699: =IF(AD699="","",AD699/$E699*100) -> 2.4 | AU699: =IF(AE699="","",AE699/$E699*100) -> 2.8 | AV699: =IF(AF699="","",AF699/$E699*100) -> 2.8 | AW699: =IF(AG699="","",AG699/$E699*100) -> 3.4 | AX699: =IF(AH699="","",AH699/$E699*100) -> 1.8 | ... BF699: =IF(AP699="","",AP699/$E699*100) -> 1.2
A700: RP68511 | E700: 500 | F700: 93.8 | G700: 93.8 | H700: =ABS(F700-G700) -> 0 | I700: 91.97 | J700: 1.83 | AB700: 2 | AC700: 12 | AD700: 12 | AE700: 12 | AF700: 12 | AH700: 11 | AI700: 22 | AK700: 9 | AL700: 3 | AP700: 12 | AQ700: =IF(AA700="","",AA700/$E700*100) | AR700: =IF(AB700="","",AB700/$E700*100) -> 0.4 | AS700: =IF(AC700="","",AC700/$E700*100) -> 2.4 | AT700: =IF(AD700="","",AD700/$E700*100) -> 2.4 | AU700: =IF(AE700="","",AE700/$E700*100) -> 2.4 | AV700: =IF(AF700="","",AF700/$E700*100) -> 2.4 | AW700: =IF(AG700="","",AG700/$E700*100) | AX700: =IF(AH700="","",AH700/$E700*100) -> 2.2 | ... BF700: =IF(AP700="","",AP700/$E700*100) -> 2.4
A701: RP68512 | B701: P40AR002N20003U | C701: 03U | D701: 03U | E701: 500 | F701: 96.6 | G701: 96.6 | H701: =ABS(F701-G701) -> 0 | I701: 95.14 | J701: 1.46 | K701: 0.442888 | L701: 0.481062 | M701: 0.27438697 | N701: -0.38260692 | O701: 0.4935336 | P701: -0.61563544 | Q701: 2.4283231 | R701: 2.5935223 | S701: 3.4238776 | T701: 21.43664 | U701: 21.46371 | V701: 21.4976 | W701: 0.32274542 | X701: -0.35339919 | Y701: 0.060777328 | Z701: 0.025995943 | AA701: 0 | AB701: 0 | AC701: 9 | AD701: 9 | AE701: 9 | AF701: 9 | AG701: 11 | AH701: 5 | AI701: 10 | AJ701: 6 | AK701: 4 | AL701: 0 | AM701: 9 | AN701: 9 | AO701: 6 | AP701: 7 | AQ701: =IF(AA701="","",AA701/$E701*100) -> 0 | AR701: =IF(AB701="","",AB701/$E701*100) -> 0 | AS701: =IF(AC701="","",AC701/$E701*100) -> 1.8 | AT701: =IF(AD701="","",AD701/$E701*100) -> 1.8 | AU701: =IF(AE701="","",AE701/$E701*100) -> 1.8 | AV701: =IF(AF701="","",AF701/$E701*100) -> 1.8 | AW701: =IF(AG701="","",AG701/$E701*100) -> 2.2 | AX701: =IF(AH701="","",AH701/$E701*100) -> 1 | ... BF701: =IF(AP701="","",AP701/$E701*100) -> 1.4
A702: RP68513 | B702: P40AR002N20003U | C702: 03U | D702: 03U | E702: 500 | F702: 98.2 | G702: 98.2 | H702: =ABS(F702-G702) -> 0 | I702: 95.8 | J702: 2.4 | K702: 0.4458396 | L702: 0.48477555 | M702: 0.31111336 | N702: -0.46694939 | O702: 0.64441296 | P702: -0.84260729 | Q702: 2.2721907 | R702: 2.4356566 | S702: 4.3007895 | T702: 21.613737 | U702: 21.631006 | V702: 21.665708 | W702: 0.40786235 | X702: -0.4302915 | Y702: 0.067314516 | Z702: 0.033290323 | AA702: 0 | AB702: 1 | AC702: 6 | AD702: 6 | AE702: 6 | AF702: 6 | AG702: 7 | AH702: 4 | AI702: 6 | AJ702: 5 | AK702: 2 | AL702: 1 | AM702: 6 | AN702: 6 | AO702: 4 | AP702: 4 | AQ702: =IF(AA702="","",AA702/$E702*100) -> 0 | AR702: =IF(AB702="","",AB702/$E702*100) -> 0.2 | AS702: =IF(AC702="","",AC702/$E702*100) -> 1.2 | AT702: =IF(AD702="","",AD702/$E702*100) -> 1.2 | AU702: =IF(AE702="","",AE702/$E702*100) -> 1.2 | AV702: =IF(AF702="","",AF702/$E702*100) -> 1.2 | AW702: =IF(AG702="","",AG702/$E702*100) -> 1.4 | AX702: =IF(AH702="","",AH702/$E702*100) -> 0.8 | ... BF702: =IF(AP702="","",AP702/$E702*100) -> 0.8
A703: RP68514 | B703: P40AR002N20003U | C703: 03U | D703: 03U | E703: 500 | F703: 91.2 | G703: 91.2 | H703: =ABS(F703-G703) -> 0 | I703: 89.5 | J703: 1.7 | K703: 0.4452176 | L703: 0.49007114 | M703: 0.30820127 | N703: -0.46714407 | O703: 0.72236864 | P703: -0.87791102 | Q703: 2.385629 | R703: 2.5448857 | S703: 5.6567888 | T703: 21.215336 | U703: 21.245303 | V703: 21.26714 | W703: 0.37901483 | X703: -0.44747881 | Y703: 0.074575 | Z703: 0.027891892 | AA703: 0 | AB703: 8 | AC703: 28 | AD703: 28 | AE703: 28 | AF703: 28 | AG703: 31 | AH703: 17 | AI703: 36 | AJ703: 24 | AK703: 17 | AL703: 3 | AM703: 28 | AN703: 28 | AO703: 20 | AP703: 19 | AQ703: =IF(AA703="","",AA703/$E703*100) -> 0 | AR703: =IF(AB703="","",AB703/$E703*100) -> 1.6 | AS703: =IF(AC703="","",AC703/$E703*100) -> 5.6 | AT703: =IF(AD703="","",AD703/$E703*100) -> 5.6 | AU703: =IF(AE703="","",AE703/$E703*100) -> 5.6 | AV703: =IF(AF703="","",AF703/$E703*100) -> 5.6 | AW703: =IF(AG703="","",AG703/$E703*100) -> 6.2 | AX703: =IF(AH703="","",AH703/$E703*100) -> 3.4 | ... BF703: =IF(AP703="","",AP703/$E703*100) -> 3.8
A704: RP68515 | B704: P40AR002N20003U | C704: 03U | D704: 03U | E704: 500 | F704: 96.8 | G704: 96.8 | H704: =ABS(F704-G704) -> 0 | I704: 95.23 | J704: 1.57 | K704: 0.4400356 | L704: 0.47899197 | M704: 0.29722358 | N704: -0.41944715 | O704: 0.53893075 | P704: -0.69851527 | Q704: 2.4007536 | R704: 2.5672177 | S704: 3.646714 | T704: 21.412274 | U704: 21.435211 | V704: 21.459759 | W704: 0.36350102 | X704: -0.38139308 | Y704: 0.046189516 | Z704: 0.027483871 | AA704: 0 | AB704: 2 | AC704: 8 | AD704: 8 | AE704: 9 | AF704: 9 | AG704: 9 | AH704: 4 | AI704: 7 | AJ704: 3 | AK704: 3 | AL704: 2 | AM704: 9 | AN704: 9 | AO704: 4 | AP704: 4 | AQ704: =IF(AA704="","",AA704/$E704*100) -> 0 | AR704: =IF(AB704="","",AB704/$E704*100) -> 0.4 | AS704: =IF(AC704="","",AC704/$E704*100) -> 1.6 | AT704: =IF(AD704="","",AD704/$E704*100) -> 1.6 | AU704: =IF(AE704="","",AE704/$E704*100) -> 1.8 | AV704: =IF(AF704="","",AF704/$E704*100) -> 1.8 | AW704: =IF(AG704="","",AG704/$E704*100) -> 1.8 | AX704: =IF(AH704="","",AH704/$E704*100) -> 0.8 | ... BF704: =IF(AP704="","",AP704/$E704*100) -> 0.8
A705: RP68516 | B705: P40AR002N20003U | C705: 03U | D705: 03U | E705: 500 | F705: 96.6 | G705: 96.6 | H705: =ABS(F705-G705) -> 0 | I705: 94.42 | J705: 2.18 | K705: 0.445338 | L705: 0.48681452 | M705: 0.30924187 | N705: -0.46424797 | O705: 0.69579022 | P705: -0.85296538 | Q705: 2.197541 | R705: 2.3578119 | S705: 5.2700266 | T705: 21.278439 | U705: 21.326176 | V705: 21.356137 | W705: 0.38082114 | X705: -0.44057114 | Y705: 0.080684426 | Z705: 0.028353909 | AA705: 0 | AB705: 4 | AC705: 8 | AD705: 8 | AE705: 9 | AF705: 8 | AG705: 12 | AH705: 10 | AI705: 12 | AJ705: 13 | AK705: 11 | AL705: 3 | AM705: 8 | AN705: 8 | AO705: 12 | AP705: 14 | AQ705: =IF(AA705="","",AA705/$E705*100) -> 0 | AR705: =IF(AB705="","",AB705/$E705*100) -> 0.8 | AS705: =IF(AC705="","",AC705/$E705*100) -> 1.6 | AT705: =IF(AD705="","",AD705/$E705*100) -> 1.6 | AU705: =IF(AE705="","",AE705/$E705*100) -> 1.8 | AV705: =IF(AF705="","",AF705/$E705*100) -> 1.6 | AW705: =IF(AG705="","",AG705/$E705*100) -> 2.4 | AX705: =IF(AH705="","",AH705/$E705*100) -> 2 | ... BF705: =IF(AP705="","",AP705/$E705*100) -> 2.8
A706: RP68519 | B706: P40AR002N20003U | C706: 03U | D706: 03U | E706: 500 | F706: 97.8 | G706: 97.8 | H706: =ABS(F706-G706) -> 0 | I706: 95.52 | J706: 2.28 | K706: 0.4401124 | L706: 0.47988978 | M706: 0.27804858 | N706: -0.3868502 | O706: 0.49947571 | P706: -0.61154656 | Q706: 2.2620732 | R706: 2.4265789 | S706: 4.7496334 | T706: 21.406275 | U706: 21.441212 | V706: 21.472345 | W706: 0.32703239 | X706: -0.35961336 | Y706: 0.063509128 | Z706: 0.032518219 | AA706: 0 | AB706: 1 | AC706: 6 | AD706: 6 | AE706: 6 | AF706: 6 | AG706: 8 | AH706: 6 | AI706: 9 | AJ706: 6 | AK706: 5 | AL706: 1 | AM706: 6 | AN706: 6 | AO706: 7 | AP706: 6 | AQ706: =IF(AA706="","",AA706/$E706*100) -> 0 | AR706: =IF(AB706="","",AB706/$E706*100) -> 0.2 | AS706: =IF(AC706="","",AC706/$E706*100) -> 1.2 | AT706: =IF(AD706="","",AD706/$E706*100) -> 1.2 | AU706: =IF(AE706="","",AE706/$E706*100) -> 1.2 | AV706: =IF(AF706="","",AF706/$E706*100) -> 1.2 | AW706: =IF(AG706="","",AG706/$E706*100) -> 1.6 | AX706: =IF(AH706="","",AH706/$E706*100) -> 1.2 | ... BF706: =IF(AP706="","",AP706/$E706*100) -> 1.2
A707: RP68520 | B707: P40AR002N20003U | C707: 03U | D707: 03U | E707: 500 | F707: 34.6 | G707: 34.6 | H707: =ABS(F707-G707) -> 0 | I707: 93.28 | J707: -58.68 | K707: 0.3691716 | L707: 0.48344647 | M707: 0.30961878 | N707: -0.46083425 | O707: 0.66931429 | P707: -0.84692571 | Q707: 2.2491005 | R707: 2.3826724 | S707: 6.0459184 | T707: 20.983509 | U707: 21.18354 | V707: 21.37462 | W707: 0.38509143 | X707: -0.42856571 | Y707: 0.40585965 | Z707: 0.034264957 | AA707: 0 | AB707: 61 | AC707: 319 | AD707: 319 | AE707: 325 | AF707: 325 | AG707: 311 | AH707: 262 | AI707: 255 | AJ707: 215 | AK707: 172 | AL707: 39 | AM707: 325 | AN707: 325 | AO707: 215 | AP707: 266 | AQ707: =IF(AA707="","",AA707/$E707*100) -> 0 | AR707: =IF(AB707="","",AB707/$E707*100) -> 12.2 | AS707: =IF(AC707="","",AC707/$E707*100) -> 63.8 | AT707: =IF(AD707="","",AD707/$E707*100) -> 63.8 | AU707: =IF(AE707="","",AE707/$E707*100) -> 65 | AV707: =IF(AF707="","",AF707/$E707*100) -> 65 | AW707: =IF(AG707="","",AG707/$E707*100) -> 62.2 | AX707: =IF(AH707="","",AH707/$E707*100) -> 52.4 | ... BF707: =IF(AP707="","",AP707/$E707*100) -> 53.2
A708: RP68521 | B708: P40AR002N20003U | C708: 03U | D708: 03U | E708: 500 | F708: 91.2 | G708: 91.2 | H708: =ABS(F708-G708) -> 0 | I708: 91.74 | J708: -0.54 | K708: 0.4435436 | L708: 0.4869899 | M708: 0.28732397 | N708: -0.43621166 | O708: 0.61715551 | P708: -0.77639525 | Q708: 2.2380346 | R708: 2.3959494 | S708: 5.3459705 | T708: 21.582218 | U708: 21.619497 | V708: 21.651534 | W708: 0.36476674 | X708: -0.41243413 | Y708: 0.088835073 | Z708: 0.024132479 | AA708: 0 | AB708: 5 | AC708: 37 | AD708: 37 | AE708: 37 | AF708: 37 | AG708: 37 | AH708: 24 | AI708: 26 | AJ708: 22 | AK708: 16 | AL708: 3 | AM708: 37 | AN708: 37 | AO708: 21 | AP708: 32 | AQ708: =IF(AA708="","",AA708/$E708*100) -> 0 | AR708: =IF(AB708="","",AB708/$E708*100) -> 1 | AS708: =IF(AC708="","",AC708/$E708*100) -> 7.4 | AT708: =IF(AD708="","",AD708/$E708*100) -> 7.4 | AU708: =IF(AE708="","",AE708/$E708*100) -> 7.4 | AV708: =IF(AF708="","",AF708/$E708*100) -> 7.4 | AW708: =IF(AG708="","",AG708/$E708*100) -> 7.4 | AX708: =IF(AH708="","",AH708/$E708*100) -> 4.8 | ... BF708: =IF(AP708="","",AP708/$E708*100) -> 6.4
A709: RP68522 | B709: P40AR002N20003U | C709: 03U | D709: 03U | E709: 500 | F709: 96.4 | G709: 96.6 | H709: =ABS(F709-G709) -> 0.2 | I709: 94.42 | J709: 2.18 | K709: 0.4390312 | L709: 0.47827455 | M709: 0.30259305 | N709: -0.42826994 | O709: 0.55472597 | P709: -0.6992454 | Q709: 2.2939344 | R709: 2.4560081 | S709: 4.1299389 | T709: 21.358012 | U709: 21.387424 | V709: 21.417339 | W709: 0.36908998 | X709: -0.38778303 | Y709: 0.058511156 | Z709: 0.028843813 | AA709: 0 | AB709: 1 | AC709: 11 | AD709: 11 | AE709: 11 | AF709: 11 | AG709: 12 | AH709: 4 | AI709: 9 | AJ709: 7 | AK709: 5 | AL709: 2 | AM709: 11 | AN709: 11 | AO709: 7 | AP709: 7 | AQ709: =IF(AA709="","",AA709/$E709*100) -> 0 | AR709: =IF(AB709="","",AB709/$E709*100) -> 0.2 | AS709: =IF(AC709="","",AC709/$E709*100) -> 2.2 | AT709: =IF(AD709="","",AD709/$E709*100) -> 2.2 | AU709: =IF(AE709="","",AE709/$E709*100) -> 2.2 | AV709: =IF(AF709="","",AF709/$E709*100) -> 2.2 | AW709: =IF(AG709="","",AG709/$E709*100) -> 2.4 | AX709: =IF(AH709="","",AH709/$E709*100) -> 0.8 | ... BF709: =IF(AP709="","",AP709/$E709*100) -> 1.4
A710: RP68523 | B710: P40AR002N20003U | C710: 03U | D710: 03U | E710: 500 | F710: 93.8 | G710: 93.8 | H710: =ABS(F710-G710) -> 0 | I710: 91.4 | J710: 2.4 | K710: 0.4451672 | L710: 0.48941414 | M710: 0.30492812 | N710: -0.51363291 | O710: 0.65429598 | P710: -0.84352008 | Q710: 2.345211 | R710: 2.5010744 | S710: 3.9129508 | T710: 21.364549 | U710: 21.392623 | V710: 21.434211 | W710: 0.38382875 | X710: -0.43517336 | Y710: 0.076843177 | Z710: 0.042829569 | AA710: 0 | AB710: 5 | AC710: 27 | AD710: 26 | AE710: 27 | AF710: 27 | AG710: 26 | AH710: 14 | AI710: 12 | AJ710: 12 | AK710: 12 | AL710: 6 | AM710: 27 | AN710: 27 | AO710: 9 | AP710: 13 | AQ710: =IF(AA710="","",AA710/$E710*100) -> 0 | AR710: =IF(AB710="","",AB710/$E710*100) -> 1 | AS710: =IF(AC710="","",AC710/$E710*100) -> 5.4 | AT710: =IF(AD710="","",AD710/$E710*100) -> 5.2 | AU710: =IF(AE710="","",AE710/$E710*100) -> 5.4 | AV710: =IF(AF710="","",AF710/$E710*100) -> 5.4 | AW710: =IF(AG710="","",AG710/$E710*100) -> 5.2 | AX710: =IF(AH710="","",AH710/$E710*100) -> 2.8 | ... BF710: =IF(AP710="","",AP710/$E710*100) -> 2.6
A711: RP68537 | B711: P40AR002N20007U | C711: 07U | D711: 07U | E711: 500 | F711: 94.2 | G711: 94.2 | H711: =ABS(F711-G711) -> 0 | I711: 92.92 | J711: 1.28 | K711: 0.4447436 | L711: 0.48488153 | M711: 0.31921996 | N711: -0.45179633 | O711: 0.60299388 | P711: -0.80686531 | Q711: 2.3015133 | R711: 2.4656275 | S711: 4.5551875 | T711: 21.341837 | U711: 21.355984 | V711: 21.393964 | W711: 0.41138493 | X711: -0.42679837 | Y711: 0.058276986 | Z711: 0.036290389 | AA711: 0 | AB711: 2 | AC711: 9 | AD711: 9 | AE711: 10 | AF711: 10 | AG711: 11 | AH711: 6 | AI711: 20 | AJ711: 10 | AK711: 6 | AL711: 2 | AM711: 9 | AN711: 9 | AO711: 9 | AP711: 11 | AQ711: =IF(AA711="","",AA711/$E711*100) -> 0 | AR711: =IF(AB711="","",AB711/$E711*100) -> 0.4 | AS711: =IF(AC711="","",AC711/$E711*100) -> 1.8 | AT711: =IF(AD711="","",AD711/$E711*100) -> 1.8 | AU711: =IF(AE711="","",AE711/$E711*100) -> 2 | AV711: =IF(AF711="","",AF711/$E711*100) -> 2 | AW711: =IF(AG711="","",AG711/$E711*100) -> 2.2 | AX711: =IF(AH711="","",AH711/$E711*100) -> 1.2 | ... BF711: =IF(AP711="","",AP711/$E711*100) -> 2.2
A712: RP68538 | B712: P40AR002N20007U | C712: 07U | D712: 07U | E712: 500 | F712: 92.6 | G712: 92.6 | H712: =ABS(F712-G712) -> 0 | I712: 91.36 | J712: 1.24 | K712: 0.4345316 | L712: 0.47716397 | M712: 0.2943706 | N712: -0.41345963 | O712: 0.52824224 | P712: -0.66837474 | Q712: 2.2812076 | R712: 2.4409072 | S712: 4.4387021 | T712: 21.300422 | U712: 21.322547 | V712: 21.349287 | W712: 0.34596273 | X712: -0.37691322 | Y712: 0.063169102 | Z712: 0.032350731 | AA712: 0 | AB712: 6 | AC712: 17 | AD712: 17 | AE712: 17 | AF712: 17 | AG712: 28 | AH712: 14 | AI712: 30 | AJ712: 26 | AK712: 21 | AL712: 8 | AM712: 17 | AN712: 16 | AO712: 21 | AP712: 21 | AQ712: =IF(AA712="","",AA712/$E712*100) -> 0 | AR712: =IF(AB712="","",AB712/$E712*100) -> 1.2 | AS712: =IF(AC712="","",AC712/$E712*100) -> 3.4 | AT712: =IF(AD712="","",AD712/$E712*100) -> 3.4 | AU712: =IF(AE712="","",AE712/$E712*100) -> 3.4 | AV712: =IF(AF712="","",AF712/$E712*100) -> 3.4 | AW712: =IF(AG712="","",AG712/$E712*100) -> 5.6 | AX712: =IF(AH712="","",AH712/$E712*100) -> 2.8 | ... BF712: =IF(AP712="","",AP712/$E712*100) -> 4.2
... A1228: RP69328 | B1228: P40AR002N20004U | C1228: 04U | D1228: 04U | E1228: 500 | F1228: 95.8 | G1228: 95.8 | H1228: =ABS(F1228-G1228) -> 0 | I1228: 93.74 | J1228: 2.06 | K1228: 0.4418524 | L1228: 0.48218273 | M1228: 0.35493293 | N1228: -0.52517683 | O1228: 0.8159878 | P1228: -1.0107378 | Q1228: 2.1114079 | R1228: 2.2666049 | S1228: 3.9950311 | T1228: 20.905133 | U1228: 20.928455 | V1228: 20.959476 | W1228: 0.47327236 | X1228: -0.49160976 | Y1228: 0.062282209 | Z1228: 0.034069106 | AA1228: 0 | AB1228: 2 | AC1228: 8 | AD1228: 8 | AE1228: 8 | AF1228: 8 | AG1228: 17 | AH1228: 13 | AI1228: 17 | AJ1228: 13 | AK1228: 8 | AL1228: 4 | AM1228: 8 | AN1228: 8 | AO1228: 11 | AP1228: 8 | AQ1228: =IF(AA1228="","",AA1228/$E1228*100) -> 0 | AR1228: =IF(AB1228="","",AB1228/$E1228*100) -> 0.4 | AS1228: =IF(AC1228="","",AC1228/$E1228*100) -> 1.6 | AT1228: =IF(AD1228="","",AD1228/$E1228*100) -> 1.6 | AU1228: =IF(AE1228="","",AE1228/$E1228*100) -> 1.6 | AV1228: =IF(AF1228="","",AF1228/$E1228*100) -> 1.6 | AW1228: =IF(AG1228="","",AG1228/$E1228*100) -> 3.4 | AX1228: =IF(AH1228="","",AH1228/$E1228*100) -> 2.6 | ... BF1228: =IF(AP1228="","",AP1228/$E1228*100) -> 1.6
A1229: RP69329 | B1229: P40AR002N20004U | C1229: 04U | D1229: 04U | E1229: 500 | F1229: 94.6 | G1229: 94.6 | H1229: =ABS(F1229-G1229) -> 0 | K1229: 0.4439092 | L1229: 0.48587879 | M1229: 0.33005967 | N1229: -0.48420782 | O1229: 0.73726132 | P1229: -0.90841358 | Q1229: 2.0946901 | R1229: 2.2479796 | S1229: 6.4937705 | T1229: 20.632994 | U1229: 20.656795 | V1229: 20.690524 | W1229: 0.37695885 | X1229: -0.44561111 | Y1229: 0.056576065 | Z1229: 0.029369919 | AA1229: 0 | AB1229: 5 | AC1229: 14 | AD1229: 14 | AE1229: 14 | AF1229: 14 | AG1229: 16 | AH1229: 9 | AI1229: 12 | AJ1229: 9 | AK1229: 7 | AL1229: 4 | AM1229: 14 | AN1229: 14 | AO1229: 7 | AP1229: 8 | AQ1229: =IF(AA1229="","",AA1229/$E1229*100) -> 0 | AR1229: =IF(AB1229="","",AB1229/$E1229*100) -> 1 | AS1229: =IF(AC1229="","",AC1229/$E1229*100) -> 2.8 | AT1229: =IF(AD1229="","",AD1229/$E1229*100) -> 2.8 | AU1229: =IF(AE1229="","",AE1229/$E1229*100) -> 2.8 | AV1229: =IF(AF1229="","",AF1229/$E1229*100) -> 2.8 | AW1229: =IF(AG1229="","",AG1229/$E1229*100) -> 3.2 | AX1229: =IF(AH1229="","",AH1229/$E1229*100) -> 1.8 | ... BF1229: =IF(AP1229="","",AP1229/$E1229*100) -> 1.6
A1230: RP69330 | B1230: P40AR002N20004U | C1230: 04U | D1230: 04U | E1230: 500 | F1230: 94.2 | G1230: 94.2 | H1230: =ABS(F1230-G1230) -> 0 | I1230: 92.18 | J1230: 2.02 | K1230: 0.4356212 | L1230: 0.4778664 | M1230: 0.31467076 | N1230: -0.44047035 | O1230: 0.57634765 | P1230: -0.7630409 | Q1230: 2.1432075 | R1230: 2.2982645 | S1230: 3.1821206 | T1230: 20.890329 | U1230: 20.918609 | V1230: 20.948692 | W1230: 0.40178323 | X1230: -0.39249693 | Y1230: 0.05992623 | Z1230: 0.02654433 | AA1230: 0 | AB1230: 6 | AC1230: 11 | AD1230: 11 | AE1230: 11 | AF1230: 11 | AG1230: 23 | AH1230: 13 | AI1230: 19 | AJ1230: 14 | AK1230: 10 | AL1230: 2 | AM1230: 11 | AN1230: 11 | AO1230: 12 | AP1230: 15 | AQ1230: =IF(AA1230="","",AA1230/$E1230*100) -> 0 | AR1230: =IF(AB1230="","",AB1230/$E1230*100) -> 1.2 | AS1230: =IF(AC1230="","",AC1230/$E1230*100) -> 2.2 | AT1230: =IF(AD1230="","",AD1230/$E1230*100) -> 2.2 | AU1230: =IF(AE1230="","",AE1230/$E1230*100) -> 2.2 | AV1230: =IF(AF1230="","",AF1230/$E1230*100) -> 2.2 | AW1230: =IF(AG1230="","",AG1230/$E1230*100) -> 4.6 | AX1230: =IF(AH1230="","",AH1230/$E1230*100) -> 2.6 | ... BF1230: =IF(AP1230="","",AP1230/$E1230*100) -> 3
A1231: RP69331 | B1231: P40AR002N20004U | C1231: 04U | D1231: 04U | E1231: 500 | F1231: 93.4 | G1231: 93.4 | H1231: =ABS(F1231-G1231) -> 0 | I1231: 93.41 | J1231: -0.01 | K1231: 0.449644 | L1231: 0.487408 | M1231: 0.31265145 | N1231: -0.46077593 | O1231: 0.69704357 | P1231: -0.85987344 | Q1231: 2.2557917 | R1231: 2.4128893 | S1231: 4.9382917 | T1231: 21.072857 | U1231: 21.111359 | V1231: 21.146092 | W1231: 0.38688382 | X1231: -0.43308921 | Y1231: 0.062840164 | Z1231: 0.028417178 | AA1231: 0 | AB1231: 0 | AC1231: 18 | AD1231: 18 | AE1231: 18 | AF1231: 18 | AG1231: 20 | AH1231: 12 | AI1231: 20 | AJ1231: 10 | AK1231: 7 | AL1231: 1 | AM1231: 18 | AN1231: 18 | AO1231: 12 | AP1231: 11 | AQ1231: =IF(AA1231="","",AA1231/$E1231*100) -> 0 | AR1231: =IF(AB1231="","",AB1231/$E1231*100) -> 0 | AS1231: =IF(AC1231="","",AC1231/$E1231*100) -> 3.6 | AT1231: =IF(AD1231="","",AD1231/$E1231*100) -> 3.6 | AU1231: =IF(AE1231="","",AE1231/$E1231*100) -> 3.6 | AV1231: =IF(AF1231="","",AF1231/$E1231*100) -> 3.6 | AW1231: =IF(AG1231="","",AG1231/$E1231*100) -> 4 | AX1231: =IF(AH1231="","",AH1231/$E1231*100) -> 2.4 | ... BF1231: =IF(AP1231="","",AP1231/$E1231*100) -> 2.2
A1232: RP69333 | B1232: P40AR002N20004U | C1232: 04U | D1232: 04U | E1232: 500 | F1232: 96.2 | G1232: 96.2 | H1232: =ABS(F1232-G1232) -> 0 | I1232: 93.12 | J1232: 3.08 | K1232: 0.4481684 | L1232: 0.48856914 | M1232: 0.3308313 | N1232: -0.48547561 | O1232: 0.74322764 | P1232: -0.93055285 | Q1232: 2.1307755 | R1232: 2.2874239 | S1232: 4.4722086 | T1232: 21.074542 | U1232: 21.087018 | V1232: 21.137827 | W1232: 0.40799797 | X1232: -0.46959146 | Y1232: 0.065034623 | Z1232: 0.051617108 | AA1232: 0 | AB1232: 1 | AC1232: 8 | AD1232: 8 | AE1232: 8 | AF1232: 8 | AG1232: 10 | AH1232: 6 | AI1232: 11 | AJ1232: 9 | AK1232: 6 | AL1232: 3 | AM1232: 8 | AN1232: 8 | AO1232: 9 | AP1232: 9 | AQ1232: =IF(AA1232="","",AA1232/$E1232*100) -> 0 | AR1232: =IF(AB1232="","",AB1232/$E1232*100) -> 0.2 | AS1232: =IF(AC1232="","",AC1232/$E1232*100) -> 1.6 | AT1232: =IF(AD1232="","",AD1232/$E1232*100) -> 1.6 | AU1232: =IF(AE1232="","",AE1232/$E1232*100) -> 1.6 | AV1232: =IF(AF1232="","",AF1232/$E1232*100) -> 1.6 | AW1232: =IF(AG1232="","",AG1232/$E1232*100) -> 2 | AX1232: =IF(AH1232="","",AH1232/$E1232*100) -> 1.2 | ... BF1232: =IF(AP1232="","",AP1232/$E1232*100) -> 1.8
A1233: RP69334 | B1233: P40AR002N20004U | C1233: 04U | D1233: 04U | E1233: 500 | F1233: 90.4 | G1233: 90.4 | H1233: =ABS(F1233-G1233) -> 0 | I1233: 91.05 | J1233: -0.65 | K1233: 0.4311336 | L1233: 0.47492105 | M1233: 0.34122105 | N1233: -0.47376063 | O1233: 0.63940295 | P1233: -0.8978692 | Q1233: 2.0616596 | R1233: 2.2179707 | S1233: 4.2486752 | T1233: 20.888655 | U1233: 20.940702 | V1233: 20.971919 | W1233: 0.43083544 | X1233: -0.42183333 | Y1233: 0.082214286 | Z1233: 0.027146444 | AA1233: 0 | AB1233: 6 | AC1233: 25 | AD1233: 25 | AE1233: 26 | AF1233: 26 | AG1233: 30 | AH1233: 22 | AI1233: 32 | AJ1233: 24 | AK1233: 16 | AL1233: 5 | AM1233: 26 | AN1233: 26 | AO1233: 24 | AP1233: 22 | AQ1233: =IF(AA1233="","",AA1233/$E1233*100) -> 0 | AR1233: =IF(AB1233="","",AB1233/$E1233*100) -> 1.2 | AS1233: =IF(AC1233="","",AC1233/$E1233*100) -> 5 | AT1233: =IF(AD1233="","",AD1233/$E1233*100) -> 5 | AU1233: =IF(AE1233="","",AE1233/$E1233*100) -> 5.2 | AV1233: =IF(AF1233="","",AF1233/$E1233*100) -> 5.2 | AW1233: =IF(AG1233="","",AG1233/$E1233*100) -> 6 | AX1233: =IF(AH1233="","",AH1233/$E1233*100) -> 4.4 | ... BF1233: =IF(AP1233="","",AP1233/$E1233*100) -> 4.4
A1234: RP69335 | B1234: P40AR002N20004U | C1234: 04U | D1234: 04U | E1234: 500 | F1234: 94.4 | G1234: 94.4 | H1234: =ABS(F1234-G1234) -> 0 | K1234: 0.4443692 | L1234: 0.48781452 | M1234: 0.3201898 | N1234: -0.47217755 | O1234: 0.70521677 | P1234: -0.91272336 | Q1234: 2.1316116 | R1234: 2.2838037 | S1234: 3.5322642 | T1234: 20.888223 | U1234: 20.919836 | V1234: 20.964113 | W1234: 0.40864213 | X1234: -0.45189571 | Y1234: 0.08607377 | Z1234: 0.048513238 | AA1234: 0 | AB1234: 4 | AC1234: 10 | AD1234: 10 | AE1234: 11 | AF1234: 11 | AG1234: 16 | AH1234: 11 | AI1234: 23 | AJ1234: 16 | AK1234: 11 | AL1234: 4 | AM1234: 11 | AN1234: 11 | AO1234: 12 | AP1234: 9 | AQ1234: =IF(AA1234="","",AA1234/$E1234*100) -> 0 | AR1234: =IF(AB1234="","",AB1234/$E1234*100) -> 0.8 | AS1234: =IF(AC1234="","",AC1234/$E1234*100) -> 2 | AT1234: =IF(AD1234="","",AD1234/$E1234*100) -> 2 | AU1234: =IF(AE1234="","",AE1234/$E1234*100) -> 2.2 | AV1234: =IF(AF1234="","",AF1234/$E1234*100) -> 2.2 | AW1234: =IF(AG1234="","",AG1234/$E1234*100) -> 3.2 | AX1234: =IF(AH1234="","",AH1234/$E1234*100) -> 2.2 | ... BF1234: =IF(AP1234="","",AP1234/$E1234*100) -> 1.8
A1235: RP69336 | B1235: P40AR002N20004U | C1235: 04U | D1235: 04U | E1235: 500 | F1235: 93 | G1235: 93 | H1235: =ABS(F1235-G1235) -> 0 | I1235: 92.56 | J1235: 0.44 | K1235: 0.4443336 | L1235: 0.48555823 | M1235: 0.31742331 | N1235: -0.46451534 | O1235: 0.68751534 | P1235: -0.84951844 | Q1235: 2.1409298 | R1235: 2.2990244 | S1235: 5.5344186 | T1235: 21.017805 | U1235: 21.074239 | V1235: 21.116499 | W1235: 0.38464959 | X1235: -0.43932992 | Y1235: 0.10253719 | Z1235: 0.02988843 | AA1235: 0 | AB1235: 2 | AC1235: 11 | AD1235: 11 | AE1235: 11 | AF1235: 12 | AG1235: 16 | AH1235: 8 | AI1235: 27 | AJ1235: 17 | AK1235: 7 | AL1235: 3 | AM1235: 12 | AN1235: 12 | AO1235: 16 | AP1235: 16 | AQ1235: =IF(AA1235="","",AA1235/$E1235*100) -> 0 | AR1235: =IF(AB1235="","",AB1235/$E1235*100) -> 0.4 | AS1235: =IF(AC1235="","",AC1235/$E1235*100) -> 2.2 | AT1235: =IF(AD1235="","",AD1235/$E1235*100) -> 2.2 | AU1235: =IF(AE1235="","",AE1235/$E1235*100) -> 2.2 | AV1235: =IF(AF1235="","",AF1235/$E1235*100) -> 2.4 | AW1235: =IF(AG1235="","",AG1235/$E1235*100) -> 3.2 | AX1235: =IF(AH1235="","",AH1235/$E1235*100) -> 1.6 | ... BF1235: =IF(AP1235="","",AP1235/$E1235*100) -> 3.2
A1236: RP69337 | B1236: P40AR002N20004U | C1236: 04U | D1236: 04U | E1236: 500 | F1236: 94.8 | G1236: 94.8 | H1236: =ABS(F1236-G1236) -> 0 | I1236: 92.97 | J1236: 1.83 | K1236: 0.4458492 | L1236: 0.48578715 | M1236: 0.32603462 | N1236: -0.47537678 | O1236: 0.73197963 | P1236: -0.92926069 | Q1236: 2.0998156 | R1236: 2.2498387 | S1236: 5.1207069 | T1236: 20.677778 | U1236: 20.703043 | V1236: 20.730261 | W1236: 0.38383503 | X1236: -0.44194501 | Y1236: 0.063344262 | Z1236: 0.026934694 | AA1236: 0 | AB1236: 2 | AC1236: 9 | AD1236: 9 | AE1236: 9 | AF1236: 9 | AG1236: 12 | AH1236: 4 | AI1236: 19 | AJ1236: 14 | AK1236: 7 | AL1236: 1 | AM1236: 9 | AN1236: 9 | AO1236: 12 | AP1236: 10 | AQ1236: =IF(AA1236="","",AA1236/$E1236*100) -> 0 | AR1236: =IF(AB1236="","",AB1236/$E1236*100) -> 0.4 | AS1236: =IF(AC1236="","",AC1236/$E1236*100) -> 1.8 | AT1236: =IF(AD1236="","",AD1236/$E1236*100) -> 1.8 | AU1236: =IF(AE1236="","",AE1236/$E1236*100) -> 1.8 | AV1236: =IF(AF1236="","",AF1236/$E1236*100) -> 1.8 | AW1236: =IF(AG1236="","",AG1236/$E1236*100) -> 2.4 | AX1236: =IF(AH1236="","",AH1236/$E1236*100) -> 0.8 | ... BF1236: =IF(AP1236="","",AP1236/$E1236*100) -> 2
A1237: RP69338 | B1237: P40AR002N20004U | C1237: 04U | D1237: 04U | E1237: 500 | F1237: 93.4 | G1237: 93.6 | H1237: =ABS(F1237-G1237) -> 0.2 | I1237: 92.09 | J1237: 1.51 | K1237: 0.4406316 | L1237: 0.48182731 | M1237: 0.34030287 | N1237: -0.50036066 | O1237: 0.72653183 | P1237: -0.91254415 | Q1237: 2.14575 | R1237: 2.304177 | S1237: 3.9737107 | T1237: 21.01219 | U1237: 21.047853 | V1237: 21.081174 | W1237: 0.48005738 | X1237: -0.46153593 | Y1237: 0.081631148 | Z1237: 0.034218107 | AA1237: 0 | AB1237: 2 | AC1237: 12 | AD1237: 12 | AE1237: 13 | AF1237: 13 | AG1237: 20 | AH1237: 13 | AI1237: 23 | AJ1237: 16 | AK1237: 11 | AL1237: 6 | AM1237: 12 | AN1237: 13 | AO1237: 12 | AP1237: 14 | AQ1237: =IF(AA1237="","",AA1237/$E1237*100) -> 0 | AR1237: =IF(AB1237="","",AB1237/$E1237*100) -> 0.4 | AS1237: =IF(AC1237="","",AC1237/$E1237*100) -> 2.4 | AT1237: =IF(AD1237="","",AD1237/$E1237*100) -> 2.4 | AU1237: =IF(AE1237="","",AE1237/$E1237*100) -> 2.6 | AV1237: =IF(AF1237="","",AF1237/$E1237*100) -> 2.6 | AW1237: =IF(AG1237="","",AG1237/$E1237*100) -> 4 | AX1237: =IF(AH1237="","",AH1237/$E1237*100) -> 2.6 | ... BF1237: =IF(AP1237="","",AP1237/$E1237*100) -> 2.8
A1238: RP69339 | B1238: P40AR002N20004U | C1238: 04U | D1238: 04U | E1238: 500 | F1238: 94.6 | G1238: 94.6 | H1238: =ABS(F1238-G1238) -> 0 | I1238: 93.07 | J1238: 1.53 | K1238: 0.4439616 | L1238: 0.4881596 | M1238: 0.31022336 | N1238: -0.44897951 | O1238: 0.67442828 | P1238: -0.82930123 | Q1238: 2.215795 | R1238: 2.3717427 | S1238: 5.62725 | T1238: 21.203734 | U1238: 21.245868 | V1238: 21.27834 | W1238: 0.37421516 | X1238: -0.42485861 | Y1238: 0.067719008 | Z1238: 0.026935551 | AA1238: 0 | AB1238: 5 | AC1238: 12 | AD1238: 12 | AE1238: 12 | AF1238: 12 | AG1238: 22 | AH1238: 18 | AI1238: 20 | AJ1238: 18 | AK1238: 16 | AL1238: 6 | AM1238: 12 | AN1238: 12 | AO1238: 16 | AP1238: 19 | AQ1238: =IF(AA1238="","",AA1238/$E1238*100) -> 0 | AR1238: =IF(AB1238="","",AB1238/$E1238*100) -> 1 | AS1238: =IF(AC1238="","",AC1238/$E1238*100) -> 2.4 | AT1238: =IF(AD1238="","",AD1238/$E1238*100) -> 2.4 | AU1238: =IF(AE1238="","",AE1238/$E1238*100) -> 2.4 | AV1238: =IF(AF1238="","",AF1238/$E1238*100) -> 2.4 | AW1238: =IF(AG1238="","",AG1238/$E1238*100) -> 4.4 | AX1238: =IF(AH1238="","",AH1238/$E1238*100) -> 3.6 | ... BF1238: =IF(AP1238="","",AP1238/$E1238*100) -> 3.8
A1239: RP69340 | B1239: P40AR002N20004U | C1239: 04U | D1239: 04U | E1239: 500 | F1239: 93.6 | G1239: 93.6 | H1239: =ABS(F1239-G1239) -> 0 | I1239: 91.88 | J1239: 1.72 | K1239: 0.4484796 | L1239: 0.48956627 | M1239: 0.33385102 | N1239: -0.48696945 | O1239: 0.71875051 | P1239: -0.92325562 | Q1239: 2.2253975 | R1239: 2.3797942 | S1239: 3.9755672 | T1239: 21.444764 | U1239: 21.483299 | V1239: 21.546939 | W1239: 0.45683061 | X1239: -0.49422653 | Y1239: 0.10226087 | Z1239: 0.053334719 | AA1239: 0 | AB1239: 2 | AC1239: 10 | AD1239: 9 | AE1239: 11 | AF1239: 11 | AG1239: 22 | AH1239: 12 | AI1239: 24 | AJ1239: 13 | AK1239: 9 | AL1239: 2 | AM1239: 10 | AN1239: 10 | AO1239: 17 | AP1239: 19 | AQ1239: =IF(AA1239="","",AA1239/$E1239*100) -> 0 | AR1239: =IF(AB1239="","",AB1239/$E1239*100) -> 0.4 | AS1239: =IF(AC1239="","",AC1239/$E1239*100) -> 2 | AT1239: =IF(AD1239="","",AD1239/$E1239*100) -> 1.8 | AU1239: =IF(AE1239="","",AE1239/$E1239*100) -> 2.2 | AV1239: =IF(AF1239="","",AF1239/$E1239*100) -> 2.2 | AW1239: =IF(AG1239="","",AG1239/$E1239*100) -> 4.4 | AX1239: =IF(AH1239="","",AH1239/$E1239*100) -> 2.4 | ... BF1239: =IF(AP1239="","",AP1239/$E1239*100) -> 3.8
A1240: RP69341 | B1240: P40AR002N20004U | C1240: 04U | D1240: 04U | E1240: 500 | F1240: 94.8 | G1240: 94.8 | H1240: =ABS(F1240-G1240) -> 0 | I1240: 93.14 | J1240: 1.66 | K1240: 0.4458788 | L1240: 0.48677666 | M1240: 0.3378 | N1240: -0.50300412 | O1240: 0.76465155 | P1240: -0.95429691 | Q1240: 2.1727536 | R1240: 2.3265306 | S1240: 3.9505567 | T1240: 20.907943 | U1240: 20.948283 | V1240: 20.980361 | W1240: 0.43241443 | X1240: -0.47814609 | Y1240: 0.072126273 | Z1240: 0.026114754 | AA1240: 0 | AB1240: 3 | AC1240: 15 | AD1240: 14 | AE1240: 15 | AF1240: 15 | AG1240: 17 | AH1240: 10 | AI1240: 15 | AJ1240: 9 | AK1240: 5 | AL1240: 1 | AM1240: 15 | AN1240: 14 | AO1240: 9 | AP1240: 12 | AQ1240: =IF(AA1240="","",AA1240/$E1240*100) -> 0 | AR1240: =IF(AB1240="","",AB1240/$E1240*100) -> 0.6 | AS1240: =IF(AC1240="","",AC1240/$E1240*100) -> 3 | AT1240: =IF(AD1240="","",AD1240/$E1240*100) -> 2.8 | AU1240: =IF(AE1240="","",AE1240/$E1240*100) -> 3 | AV1240: =IF(AF1240="","",AF1240/$E1240*100) -> 3 | AW1240: =IF(AG1240="","",AG1240/$E1240*100) -> 3.4 | AX1240: =IF(AH1240="","",AH1240/$E1240*100) -> 2 | ... BF1240: =IF(AP1240="","",AP1240/$E1240*100) -> 2.4
...
